2117
8817
8817
2117
The following will give an exception:
Traceback (most recent call last):
  File "/cwd/seamless/tests/highlevel/imperative.py", line 47, in <module>
    func0(0,0)
seamless.core.transformation.SeamlessTransformationError: Traceback (most recent call last):
  File "<seamless.core.cache.transformation_cache.DummyTransformer object at 0x7f970717c730>", line 6, in <module>
    result = func0(a=a,b=b)
  File "<seamless.core.cache.transformation_cache.DummyTransformer object at 0x7f970717c730>", line 4, in func0
    raise Exception # deliberately
Exception

*************************************************
* Standard output
*************************************************
START

*************************************************
*************************************************
Execution time: 0.0 seconds

/exception

