{}
<Silk: 2 >
None
{'type': 'integer'}
<Silk: 1 >
None
<Silk: None >
<Silk: None >
{'type': 'integer'}
<Silk: 12 >
jsonschema.exceptions.ValidationError: 1.2 is not of type 'integer'

Failed validating 'type' in schema:
    {'type': 'integer'}

On instance:
    1.2

<Silk: None >
{'type': 'integer'}
<Silk: test >
{}
<Silk: test >
{}
{'__seamless__': '0.11',
 'connections': [],
 'lib': [],
 'nodes': [{'celltype': 'structured',
            'checksum': {'auth': 'c99446f315c991d5c5e83bd65753dc1fe97448da92b5e48fe028dcbd8cb87783',
                         'schema': 'd0a1b2af1705c1b8495b00145082ef7470384e62ac1c4d9b9cdbbe0476c28f8c',
                         'value': 'c99446f315c991d5c5e83bd65753dc1fe97448da92b5e48fe028dcbd8cb87783'},
            'datatype': 'mixed',
            'hash_pattern': None,
            'path': ['a'],
            'type': 'cell'}],
 'params': {'share_namespace': 'ctx'}}
RUN VALIDATION <Silk: test >
{'validators': [{'code': 'def validation(self):\n    print("RUN VALIDATION", self)\n    assert self != "test"\n', 'language': 'python', 'name': 'validation'}]}

simplest.py EXCEPTION:
jsonschema.exceptions.ValidationError: 
************************************************************************
*  Silk validation error
************************************************************************
Traceback (most recent call last):
  File "/silk/silk/validation/validators.py", line 242, in validator_validators
    validator_func(silkobject)
  File "Silk validator 1", line 3, in validation
    assert self != "test"
AssertionError
************************************************************************


            Failed validating 'validators' in schema:
                {'validators': [{'code': 'def validation(self):\n'
                                         '    print("RUN VALIDATION", self)\n'
                                         '    assert self != "test"\n',
                                 'language': 'python',
                                 'name': 'validation'}]}

            On instance:
                'test'

/simplest.py EXCEPTION

{'__seamless__': '0.11',
 'connections': [],
 'lib': [],
 'nodes': [{'celltype': 'structured',
            'checksum': {'auth': 'c99446f315c991d5c5e83bd65753dc1fe97448da92b5e48fe028dcbd8cb87783',
                         'schema': '7a8e8e6fb89d23912b1bba61afba23226aed9bfb6e31543833267455c4ac9261',
                         'value': 'c99446f315c991d5c5e83bd65753dc1fe97448da92b5e48fe028dcbd8cb87783'},
            'datatype': 'mixed',
            'hash_pattern': None,
            'path': ['a'],
            'type': 'cell'}],
 'params': {'share_namespace': 'ctx'}}
